def test(x):
    a = x * 2
    return a

print(test(5))

#上記の条件下でエラーになる変数

#print(x)
#print(a)

'''
    これは与えられた引数を2倍して返すという単純な関数です。
    内部に引数(関数内部では変数と同じ扱い)である xと変数 aが存在しています。実はこれらの変数は関数の外からはアクセスできません。
    なんとなくですが、上記の関数を呼び出す前に xや aにアクセスしたら問題が起きそうな気がするのは分かります。
    なぜなら、一度も呼ばれていないから xや aになにも入っていないからです。
    ただ、実際には関数を呼び出した後であっても関数内の引数や変数に関数外からアクセスすることはできません。
    
    具体的には#のようなエラーとなります。



'''
